Workbook

Sheet Final RWA Taxonomy
A1: Component | B1: Governance | E1: Asset | M1: Token Properties | T1: DLT | W1: Economy
A2: Attribute | B2: Governing Law | C2: Legal Entity (Wrapper) | D2: Voting | E2: Custody Arrangement | F2: Ownership Structure | G2: Dispute Forum | H2: Claim & Rights | J2: Asset Type | K2: Verification Mechanisms | M2: Divisibility | N2: Redemption Mechanism | P2: Transferability | Q2: Source of Yield | R2: Yield Distribution Method | S2: Supply | T2: Smart Contract | U2: Chain Deployment | V2: DeFi Integrations | W2: Protocol fees | X2: Access Permissions
A3: Sub-Attribute | B3: Incorporation Jurisdiction | H3: Claim Type | I3: Entitlements | K3: Third-Party Audit | L3: On-Chain Proof | N3: Settlement Form(s) | O3: Burn | X3: Primary Market Access
A4: Definition | B4: Country or territory where the issuing legal entity is formally incorporated/registered | C4: The legal structure of the issuer | D4: Capture whether there is a voting system for tokenholders in the protocol | E4: Arrangement for safekeeping of the underlying | F4: Who holds the legal title to the underlying? | G4: Rule of Law designated for dispute resolution | H4: What does the token represent as a legal or economic claim on the underlying? | I4: What does the token give to the holder as a matter of law? Better rephrased: What actionable rights or entitlements does the token grant to the holder | J4: The category of the real-world asset underlying the token | K4: Independent audit or attestation of the underlying assets by an external firm. This is not related to smart contract audit | L4: On-chain verifiable proof of reserves or asset backing | M4: Can the token be held in sub-units, and to what precision? | N4: What does the holder receive upon redemption? | O4: Is the token burned when redeemed/cancelled? | P4: Constraints on secondary market token movement (wallet-to-wallet transfer, exchange trading). | Q4: What generates returns for the token holder | R4: How yield is delivered to token holders, if applicable | S4: Is the token's supply capped at a predetermined amount? | T4: Which functions of the project are secured, automated, executed through DLT code, and are thus on-chain? | U4: Blockchain(s) on which the token is actively issued and supported by the issuer | V4: How is the token utilized within DeFi protocols? Can it be used as Collateral? | W4: What type of Fees are being charged to the user by the protocol? | X4: Identity and eligibility requirements for acquiring tokens directly from the issuer (minting/purchasing on the PRIMARY market: directly from the issuer)
A5: Possible Values | B5: USA, BVI, Cayman Islands, Switzerland, etc | C5: Direct Issuer: LLC; Gmbh etc | Bankruptcy remote vehicle: SPV; Trust etc | D5: Yes (if so, specify if Quadratic, Single choice, Multiple selection...) | E5: Institutional custodian (regulated); Self-custodied by issuer; Multi-custodian; Decentralized custody; Trust arrangement; Vault storage (physical assets); N/A (for digital-native assets) | F5: Direct title (token holder is legal owner); Beneficial ownership (custodian holds legal title on behalf of user); SPV held; N/A | G5: USA (Federal courts),ICC Arbitration etc | H5: Direct Claim on asset; Pro-rata claim on asset (share of pooled underlying); synthetic exposure (case for derivatives: no direct claim); Debt Instrument (Claim as a creditor) | I5: Redemption right; Income distribution right; Interest entitlement; Governance/voting; Usage/access rights; Net profit participation; No additional rights beyond ownership | J5: Commodity (specify what it is); Real estate; Fixed income (government/corporate bonds); Equities; Art & collectibles; Carbon credits; etc | K5: Yes/No; frequency; provide link | L5: None; Chainlink Proof of Reserve; Smart contract oracle feed; Other | M5: Whole-unit only (minimum 1 token); Fractionalized | N5: Physical delivery (underlying asset); Cash; In-kind (other token); Combination;N/A | O5: Yes/No | P5: Unrestricted; Unrestricted with issuer freeze capability; Whitelist-restricted; Lock-up period (specify duration); Non-transferable; Conditionally restricted (specify) | Q5: None (price appreciation only); Interest income; Rental income; Revenue share; Staking rewards; Lending interest; Dividend; Coupon payments etc | R5: Rebase, Accrual, Distribution, Streaming, Buyback & Burn, Yield Stripping. Definitions: Rebasing=token balance in the wallet is algorithmically adjusted so that accrued yield is expressed as additional token units. If yield = 5% annually, after 1 year 100 tokens will become 105 tokens. Usually each token = 1$ | Accrual= The holder's token count remains permanently fixed from the moment of deposit or purchase. Yield is captured internally by the contract as an increasing exchange rate, share price, or Net Asset Value per token. A holder who deposits 1,000 USDC and receives 1,000 vault shares will, after one year of 5% yield, still hold exactly 1,000 shares, but each share is now redeemable for $1.05 of underlying value. Yield is never explicitly paid out | Distribution= The protocol collects yield from the underlying RWA (interest, rent, invoice settlements, coupons) and transfers it to holders as a separate payment token|Streaming= Yield is transmitted to holders as a continuous, per-second (or per-block) flow rather than in discrete periodic events. | Buyback & Burn = The protocol uses yield generated by the underlying RWA portfolio to purchase its own governance or utility token on the open market (via DEX swaps or OTC), then permanently destroys (burns) the purchased tokens. No yield is delivered directly to any holder in any form | Yield Stripping = A yield-bearing RWA token is decomposed into two independently tradable components: a Principal Token (PT) that entitles the holder to the face value of the underlying at a fixed maturity date, and a Yield Token (YT) that entitles the holder to all yield generated by the underlying between now and that maturity | S5: Capped (if so, specify number), Uncapped | T5: Specify which Component is implemented on-chain; or N/A | U5: Specify Chain | V5: In case it's difficult to classify use YES;NO (Collateral yes/no) Otherwise:None; Collateral in lending (specify protocols); Liquidity pool (specify); Yield vault; Structured product; Staking; Options/perps underlying; Other (specify) | W5: Minting Fee, Redemption Fee, Custody Fee, Yield Spread, Transfer Tax, management fee | X5: Permissionless (anyone can join); KYC gated; Qualified investors only; Institutional only; Whitelisted only

Sheet Classification Work
A1: Component | B1: Preliminary info | F1: Governance | I1: Asset | Q1: Token Properties | X1: DLT | AA1: Economy
A2: Attribute | F2: Governing Law | G2: Legal Entity (Wrapper) | H2: Voting | I2: Custody Arrangement | J2: Ownership Structure | K2: Dispute Forum | L2: Claim & Rights | N2: Asset Type | O2: Verification Mechanisms | Q2: Divisibility | R2: Redemption Mechanism | T2: Transferability | U2: Source of Yield | V2: Yield Distribution Method | W2: Supply | X2: Smart Contract | Y2: Chain Deployment | Z2: DeFi Integrations | AA2: Protocol fees | AB2: Access Permissions
A3: Sub-Attribute | B3: ID | C3: Protocol Name | D3: Date of Classification (DD-MM-YY) | E3: Market Cap Ranking | F3: Incorporation Jurisdiction | L3: Claim Type | M3: Entitlements | O3: Third-Party Audit | P3: On-Chain Proof | R3: Settlement Form(s) | S3: Burn | AB3: Primary Market Access
B4: 1 | C4: Tether Gold (XAUt) | D4: 46112 | E4: 1 | F4: {=_xlfn.LET( _xlpm.project,TRIM($C4), _xlpm.attribute,TRIM(IF(F$3<>"",F$3,F$2)), _xlfn.XLOOKUP( 1, (TRIM(Sources!$B$2:$B$461)=_xlpm.project)*(TRIM(Sources!$D$2:$D$461)=_xlpm.attribute), Sources!$E$2:$E$461, "UNKNOWN" ) )} -> El Salvador | G4: {=_xlfn.LET( _xlpm.project,TRIM($C4), _xlpm.attribute,TRIM(IF(G$3<>"",G$3,G$2)), _xlfn.XLOOKUP( 1, (TRIM(Sources!$B$2:$B$461)=_xlpm.project)*(TRIM(Sources!$D$2:$D$461)=_xlpm.attribute), Sources!$E$2:$E$461, "UNKNOWN" ) )} -> Direct Issuer: SA de C.V. | H4: {=_xlfn.LET( _xlpm.project,TRIM($C4), _xlpm.attribute,TRIM(IF(H$3<>"",H$3,H$2)), _xlfn.XLOOKUP( 1, (TRIM(Sources!$B$2:$B$461)=_xlpm.project)*(TRIM(Sources!$D$2:$D$461)=_xlpm.attribute), Sources!$E$2:$E$461, "UNKNOWN" ) )} -> N/A | I4: {=_xlfn.LET( _xlpm.project,TRIM($C4), _xlpm.attribute,TRIM(IF(I$3<>"",I$3,I$2)), _xlfn.XLOOKUP( 1, (TRIM(Sources!$B$2:$B$461)=_xlpm.project)*(TRIM(Sources!$D$2:$D$461)=_xlpm.attribute), Sources!$E$2:$E$461, "UNKNOWN" ) )} -> Vault storage (physical assets) | J4: {=_xlfn.LET( _xlpm.project,TRIM($C4), _xlpm.attribute,TRIM(IF(J$3<>"",J$3,J$2)), _xlfn.XLOOKUP( 1, (TRIM(Sources!$B$2:$B$461)=_xlpm.project)*(TRIM(Sources!$D$2:$D$461)=_xlpm.attribute), Sources!$E$2:$E$461, "UNKNOWN" ) )} -> Beneficial ownership (custodian holds legal title on behalf of user) | K4: {=_xlfn.LET( _xlpm.project,TRIM($C4), _xlpm.attribute,TRIM(IF(K$3<>"",K$3,K$2)), _xlfn.XLOOKUP( 1, (TRIM(Sources!$B$2:$B$461)=_xlpm.project)*(TRIM(Sources!$D$2:$D$461)=_xlpm.attribute), Sources!$E$2:$E$461, "UNKNOWN" ) )} -> CPR Arbitration; BVI law | L4: {=_xlfn.LET( _xlpm.project,TRIM($C4), _xlpm.attribute,TRIM(IF(L$3<>"",L$3,L$2)), _xlfn.XLOOKUP( 1, (TRIM(Sources!$B$2:$B$461)=_xlpm.project)*(TRIM(Sources!$D$2:$D$461)=_xlpm.attribute), Sources!$E$2:$E$461, "UNKNOWN" ) )} -> Direct Claim on asset | M4: {=_xlfn.LET( _xlpm.project,TRIM($C4), _xlpm.attribute,TRIM(IF(M$3<>"",M$3,M$2)), _xlfn.XLOOKUP( 1, (TRIM(Sources!$B$2:$B$461)=_xlpm.project)*(TRIM(Sources!$D$2:$D$461)=_xlpm.attribute), Sources!$E$2:$E$461, "UNKNOWN" ) )} -> Redemption right | ... AB4: {=_xlfn.LET( _xlpm.project,TRIM($C4), _xlpm.attribute,TRIM(IF(AB$3<>"",AB$3,AB$2)), _xlfn.XLOOKUP( 1, (TRIM(Sources!$B$2:$B$461)=_xlpm.project)*(TRIM(Sources!$D$2:$D$461)=_xlpm.attribute), Sources!$E$2:$E$461, "UNKNOWN" ) )} -> KYC gated
B5: 2 | C5: BUIDL | D5: 46112 | E5: 2 | F5: {=_xlfn.LET( _xlpm.project,TRIM($C5), _xlpm.attribute,TRIM(IF(F$3<>"",F$3,F$2)), _xlfn.XLOOKUP( 1, (TRIM(Sources!$B$2:$B$461)=_xlpm.project)*(TRIM(Sources!$D$2:$D$461)=_xlpm.attribute), Sources!$E$2:$E$461, "UNKNOWN" ) )} -> BVI | G5: {=_xlfn.LET( _xlpm.project,TRIM($C5), _xlpm.attribute,TRIM(IF(G$3<>"",G$3,G$2)), _xlfn.XLOOKUP( 1, (TRIM(Sources!$B$2:$B$461)=_xlpm.project)*(TRIM(Sources!$D$2:$D$461)=_xlpm.attribute), Sources!$E$2:$E$461, "UNKNOWN" ) )} -> Direct Issuer: Ltd. | H5: {=_xlfn.LET( _xlpm.project,TRIM($C5), _xlpm.attribute,TRIM(IF(H$3<>"",H$3,H$2)), _xlfn.XLOOKUP( 1, (TRIM(Sources!$B$2:$B$461)=_xlpm.project)*(TRIM(Sources!$D$2:$D$461)=_xlpm.attribute), Sources!$E$2:$E$461, "UNKNOWN" ) )} -> No token-holder voting system identified for the tokenized fund; BUIDL is not DAO-governed. | I5: {=_xlfn.LET( _xlpm.project,TRIM($C5), _xlpm.attribute,TRIM(IF(I$3<>"",I$3,I$2)), _xlfn.XLOOKUP( 1, (TRIM(Sources!$B$2:$B$461)=_xlpm.project)*(TRIM(Sources!$D$2:$D$461)=_xlpm.attribute), Sources!$E$2:$E$461, "UNKNOWN" ) )} -> Institutional custodian (regulated) | J5: {=_xlfn.LET( _xlpm.project,TRIM($C5), _xlpm.attribute,TRIM(IF(J$3<>"",J$3,J$2)), _xlfn.XLOOKUP( 1, (TRIM(Sources!$B$2:$B$461)=_xlpm.project)*(TRIM(Sources!$D$2:$D$461)=_xlpm.attribute), Sources!$E$2:$E$461, "UNKNOWN" ) )} -> Beneficial ownership (custodian holds legal title on behalf of user) | K5: {=_xlfn.LET( _xlpm.project,TRIM($C5), _xlpm.attribute,TRIM(IF(K$3<>"",K$3,K$2)), _xlfn.XLOOKUP( 1, (TRIM(Sources!$B$2:$B$461)=_xlpm.project)*(TRIM(Sources!$D$2:$D$461)=_xlpm.attribute), Sources!$E$2:$E$461, "UNKNOWN" ) )} -> Delaware, Disputes resolved in New York | L5: {=_xlfn.LET( _xlpm.project,TRIM($C5), _xlpm.attribute,TRIM(IF(L$3<>"",L$3,L$2)), _xlfn.XLOOKUP( 1, (TRIM(Sources!$B$2:$B$461)=_xlpm.project)*(TRIM(Sources!$D$2:$D$461)=_xlpm.attribute), Sources!$E$2:$E$461, "UNKNOWN" ) )} -> Pro-rata claim on asset (share of pooled underlying) | M5: {=_xlfn.LET( _xlpm.project,TRIM($C5), _xlpm.attribute,TRIM(IF(M$3<>"",M$3,M$2)), _xlfn.XLOOKUP( 1, (TRIM(Sources!$B$2:$B$461)=_xlpm.project)*(TRIM(Sources!$D$2:$D$461)=_xlpm.attribute), Sources!$E$2:$E$461, "UNKNOWN" ) )} -> Redemption right; Income distribution right | ... AB5: {=_xlfn.LET( _xlpm.project,TRIM($C5), _xlpm.attribute,TRIM(IF(AB$3<>"",AB$3,AB$2)), _xlfn.XLOOKUP( 1, (TRIM(Sources!$B$2:$B$461)=_xlpm.project)*(TRIM(Sources!$D$2:$D$461)=_xlpm.attribute), Sources!$E$2:$E$461, "UNKNOWN" ) )} -> Qualified investors only
B6: 3 | C6: PAX Gold | D6: 46113 | E6: 3 | F6: {=_xlfn.LET( _xlpm.project,TRIM($C6), _xlpm.attribute,TRIM(IF(F$3<>"",F$3,F$2)), _xlfn.XLOOKUP( 1, (TRIM(Sources!$B$2:$B$461)=_xlpm.project)*(TRIM(Sources!$D$2:$D$461)=_xlpm.attribute), Sources!$E$2:$E$461, "UNKNOWN" ) )} -> USA | G6: {=_xlfn.LET( _xlpm.project,TRIM($C6), _xlpm.attribute,TRIM(IF(G$3<>"",G$3,G$2)), _xlfn.XLOOKUP( 1, (TRIM(Sources!$B$2:$B$461)=_xlpm.project)*(TRIM(Sources!$D$2:$D$461)=_xlpm.attribute), Sources!$E$2:$E$461, "UNKNOWN" ) )} -> Direct Issuer: N.A. | H6: {=_xlfn.LET( _xlpm.project,TRIM($C6), _xlpm.attribute,TRIM(IF(H$3<>"",H$3,H$2)), _xlfn.XLOOKUP( 1, (TRIM(Sources!$B$2:$B$461)=_xlpm.project)*(TRIM(Sources!$D$2:$D$461)=_xlpm.attribute), Sources!$E$2:$E$461, "UNKNOWN" ) )} -> No voting system identified. | I6: {=_xlfn.LET( _xlpm.project,TRIM($C6), _xlpm.attribute,TRIM(IF(I$3<>"",I$3,I$2)), _xlfn.XLOOKUP( 1, (TRIM(Sources!$B$2:$B$461)=_xlpm.project)*(TRIM(Sources!$D$2:$D$461)=_xlpm.attribute), Sources!$E$2:$E$461, "UNKNOWN" ) )} -> Vault storage (physical assets) | J6: {=_xlfn.LET( _xlpm.project,TRIM($C6), _xlpm.attribute,TRIM(IF(J$3<>"",J$3,J$2)), _xlfn.XLOOKUP( 1, (TRIM(Sources!$B$2:$B$461)=_xlpm.project)*(TRIM(Sources!$D$2:$D$461)=_xlpm.attribute), Sources!$E$2:$E$461, "UNKNOWN" ) )} -> Beneficial ownership (custodian holds legal title on behalf of user) | K6: {=_xlfn.LET( _xlpm.project,TRIM($C6), _xlpm.attribute,TRIM(IF(K$3<>"",K$3,K$2)), _xlfn.XLOOKUP( 1, (TRIM(Sources!$B$2:$B$461)=_xlpm.project)*(TRIM(Sources!$D$2:$D$461)=_xlpm.attribute), Sources!$E$2:$E$461, "UNKNOWN" ) )} -> Binding arbitration; New York law | L6: {=_xlfn.LET( _xlpm.project,TRIM($C6), _xlpm.attribute,TRIM(IF(L$3<>"",L$3,L$2)), _xlfn.XLOOKUP( 1, (TRIM(Sources!$B$2:$B$461)=_xlpm.project)*(TRIM(Sources!$D$2:$D$461)=_xlpm.attribute), Sources!$E$2:$E$461, "UNKNOWN" ) )} -> Pro-rata claim on asset (share of pooled underlying) | M6: {=_xlfn.LET( _xlpm.project,TRIM($C6), _xlpm.attribute,TRIM(IF(M$3<>"",M$3,M$2)), _xlfn.XLOOKUP( 1, (TRIM(Sources!$B$2:$B$461)=_xlpm.project)*(TRIM(Sources!$D$2:$D$461)=_xlpm.attribute), Sources!$E$2:$E$461, "UNKNOWN" ) )} -> Redemption right | ... AB6: {=_xlfn.LET( _xlpm.project,TRIM($C6), _xlpm.attribute,TRIM(IF(AB$3<>"",AB$3,AB$2)), _xlfn.XLOOKUP( 1, (TRIM(Sources!$B$2:$B$461)=_xlpm.project)*(TRIM(Sources!$D$2:$D$461)=_xlpm.attribute), Sources!$E$2:$E$461, "UNKNOWN" ) )} -> KYC gated
B7: 4 | C7: US Yield Coin (UYSC) | D7: 46139 | E7: 4 | F7: {=_xlfn.LET( _xlpm.project,TRIM($C7), _xlpm.attribute,TRIM(IF(F$3<>"",F$3,F$2)), _xlfn.XLOOKUP( 1, (TRIM(Sources!$B$2:$B$461)=_xlpm.project)*(TRIM(Sources!$D$2:$D$461)=_xlpm.attribute), Sources!$E$2:$E$461, "UNKNOWN" ) )} -> Bermuda | G7: {=_xlfn.LET( _xlpm.project,TRIM($C7), _xlpm.attribute,TRIM(IF(G$3<>"",G$3,G$2)), _xlfn.XLOOKUP( 1, (TRIM(Sources!$B$2:$B$461)=_xlpm.project)*(TRIM(Sources!$D$2:$D$461)=_xlpm.attribute), Sources!$E$2:$E$461, "UNKNOWN" ) )} -> Direct Issuer: Ltd. | H7: {=_xlfn.LET( _xlpm.project,TRIM($C7), _xlpm.attribute,TRIM(IF(H$3<>"",H$3,H$2)), _xlfn.XLOOKUP( 1, (TRIM(Sources!$B$2:$B$461)=_xlpm.project)*(TRIM(Sources!$D$2:$D$461)=_xlpm.attribute), Sources!$E$2:$E$461, "UNKNOWN" ) )} -> UNKNOWN | I7: {=_xlfn.LET( _xlpm.project,TRIM($C7), _xlpm.attribute,TRIM(IF(I$3<>"",I$3,I$2)), _xlfn.XLOOKUP( 1, (TRIM(Sources!$B$2:$B$461)=_xlpm.project)*(TRIM(Sources!$D$2:$D$461)=_xlpm.attribute), Sources!$E$2:$E$461, "UNKNOWN" ) )} -> Institutional custodian (regulated) | J7: {=_xlfn.LET( _xlpm.project,TRIM($C7), _xlpm.attribute,TRIM(IF(J$3<>"",J$3,J$2)), _xlfn.XLOOKUP( 1, (TRIM(Sources!$B$2:$B$461)=_xlpm.project)*(TRIM(Sources!$D$2:$D$461)=_xlpm.attribute), Sources!$E$2:$E$461, "UNKNOWN" ) )} -> Beneficial ownership (custodian holds legal title on behalf of user) | K7: {=_xlfn.LET( _xlpm.project,TRIM($C7), _xlpm.attribute,TRIM(IF(K$3<>"",K$3,K$2)), _xlfn.XLOOKUP( 1, (TRIM(Sources!$B$2:$B$461)=_xlpm.project)*(TRIM(Sources!$D$2:$D$461)=_xlpm.attribute), Sources!$E$2:$E$461, "UNKNOWN" ) )} -> UNKNOWN | L7: {=_xlfn.LET( _xlpm.project,TRIM($C7), _xlpm.attribute,TRIM(IF(L$3<>"",L$3,L$2)), _xlfn.XLOOKUP( 1, (TRIM(Sources!$B$2:$B$461)=_xlpm.project)*(TRIM(Sources!$D$2:$D$461)=_xlpm.attribute), Sources!$E$2:$E$461, "UNKNOWN" ) )} -> Pro-rata claim on asset (share of pooled underlying) | M7: {=_xlfn.LET( _xlpm.project,TRIM($C7), _xlpm.attribute,TRIM(IF(M$3<>"",M$3,M$2)), _xlfn.XLOOKUP( 1, (TRIM(Sources!$B$2:$B$461)=_xlpm.project)*(TRIM(Sources!$D$2:$D$461)=_xlpm.attribute), Sources!$E$2:$E$461, "UNKNOWN" ) )} -> Redemption right; Interest entitlement | ... AB7: {=_xlfn.LET( _xlpm.project,TRIM($C7), _xlpm.attribute,TRIM(IF(AB$3<>"",AB$3,AB$2)), _xlfn.XLOOKUP( 1, (TRIM(Sources!$B$2:$B$461)=_xlpm.project)*(TRIM(Sources!$D$2:$D$461)=_xlpm.attribute), Sources!$E$2:$E$461, "UNKNOWN" ) )} -> Institutional only; KYC gated; Whitelisted only
B8: 5 | C8: Superstate USTB | D8: 46139 | E8: 5 | F8: {=_xlfn.LET( _xlpm.project,TRIM($C8), _xlpm.attribute,TRIM(IF(F$3<>"",F$3,F$2)), _xlfn.XLOOKUP( 1, (TRIM(Sources!$B$2:$B$461)=_xlpm.project)*(TRIM(Sources!$D$2:$D$461)=_xlpm.attribute), Sources!$E$2:$E$461, "UNKNOWN" ) )} -> USA | G8: {=_xlfn.LET( _xlpm.project,TRIM($C8), _xlpm.attribute,TRIM(IF(G$3<>"",G$3,G$2)), _xlfn.XLOOKUP( 1, (TRIM(Sources!$B$2:$B$461)=_xlpm.project)*(TRIM(Sources!$D$2:$D$461)=_xlpm.attribute), Sources!$E$2:$E$461, "UNKNOWN" ) )} -> Bankruptcy remote vehicle: Trust | H8: {=_xlfn.LET( _xlpm.project,TRIM($C8), _xlpm.attribute,TRIM(IF(H$3<>"",H$3,H$2)), _xlfn.XLOOKUP( 1, (TRIM(Sources!$B$2:$B$461)=_xlpm.project)*(TRIM(Sources!$D$2:$D$461)=_xlpm.attribute), Sources!$E$2:$E$461, "UNKNOWN" ) )} -> UNKNOWN | I8: {=_xlfn.LET( _xlpm.project,TRIM($C8), _xlpm.attribute,TRIM(IF(I$3<>"",I$3,I$2)), _xlfn.XLOOKUP( 1, (TRIM(Sources!$B$2:$B$461)=_xlpm.project)*(TRIM(Sources!$D$2:$D$461)=_xlpm.attribute), Sources!$E$2:$E$461, "UNKNOWN" ) )} -> Institutional custodian (regulated) | J8: {=_xlfn.LET( _xlpm.project,TRIM($C8), _xlpm.attribute,TRIM(IF(J$3<>"",J$3,J$2)), _xlfn.XLOOKUP( 1, (TRIM(Sources!$B$2:$B$461)=_xlpm.project)*(TRIM(Sources!$D$2:$D$461)=_xlpm.attribute), Sources!$E$2:$E$461, "UNKNOWN" ) )} -> SPV held | K8: {=_xlfn.LET( _xlpm.project,TRIM($C8), _xlpm.attribute,TRIM(IF(K$3<>"",K$3,K$2)), _xlfn.XLOOKUP( 1, (TRIM(Sources!$B$2:$B$461)=_xlpm.project)*(TRIM(Sources!$D$2:$D$461)=_xlpm.attribute), Sources!$E$2:$E$461, "UNKNOWN" ) )} -> UNKNOWN | L8: {=_xlfn.LET( _xlpm.project,TRIM($C8), _xlpm.attribute,TRIM(IF(L$3<>"",L$3,L$2)), _xlfn.XLOOKUP( 1, (TRIM(Sources!$B$2:$B$461)=_xlpm.project)*(TRIM(Sources!$D$2:$D$461)=_xlpm.attribute), Sources!$E$2:$E$461, "UNKNOWN" ) )} -> Pro-rata claim on asset (share of pooled underlying) | M8: {=_xlfn.LET( _xlpm.project,TRIM($C8), _xlpm.attribute,TRIM(IF(M$3<>"",M$3,M$2)), _xlfn.XLOOKUP( 1, (TRIM(Sources!$B$2:$B$461)=_xlpm.project)*(TRIM(Sources!$D$2:$D$461)=_xlpm.attribute), Sources!$E$2:$E$461, "UNKNOWN" ) )} -> Redemption right; Interest entitlement | ... AB8: {=_xlfn.LET( _xlpm.project,TRIM($C8), _xlpm.attribute,TRIM(IF(AB$3<>"",AB$3,AB$2)), _xlfn.XLOOKUP( 1, (TRIM(Sources!$B$2:$B$461)=_xlpm.project)*(TRIM(Sources!$D$2:$D$461)=_xlpm.attribute), Sources!$E$2:$E$461, "UNKNOWN" ) )} -> Qualified investors only; KYC gated; Whitelisted only
B9: 6 | C9: WisdomTree Treasury Money Market Digital Fund (WTGXX) | D9: 46139 | E9: 6 | F9: {=_xlfn.LET( _xlpm.project,TRIM($C9), _xlpm.attribute,TRIM(IF(F$3<>"",F$3,F$2)), _xlfn.XLOOKUP( 1, (TRIM(Sources!$B$2:$B$461)=_xlpm.project)*(TRIM(Sources!$D$2:$D$461)=_xlpm.attribute), Sources!$E$2:$E$461, "UNKNOWN" ) )} -> USA | G9: {=_xlfn.LET( _xlpm.project,TRIM($C9), _xlpm.attribute,TRIM(IF(G$3<>"",G$3,G$2)), _xlfn.XLOOKUP( 1, (TRIM(Sources!$B$2:$B$461)=_xlpm.project)*(TRIM(Sources!$D$2:$D$461)=_xlpm.attribute), Sources!$E$2:$E$461, "UNKNOWN" ) )} -> Bankruptcy remote vehicle: Trust | H9: {=_xlfn.LET( _xlpm.project,TRIM($C9), _xlpm.attribute,TRIM(IF(H$3<>"",H$3,H$2)), _xlfn.XLOOKUP( 1, (TRIM(Sources!$B$2:$B$461)=_xlpm.project)*(TRIM(Sources!$D$2:$D$461)=_xlpm.attribute), Sources!$E$2:$E$461, "UNKNOWN" ) )} -> Yes (shareholder voting; one vote per share when required) | I9: {=_xlfn.LET( _xlpm.project,TRIM($C9), _xlpm.attribute,TRIM(IF(I$3<>"",I$3,I$2)), _xlfn.XLOOKUP( 1, (TRIM(Sources!$B$2:$B$461)=_xlpm.project)*(TRIM(Sources!$D$2:$D$461)=_xlpm.attribute), Sources!$E$2:$E$461, "UNKNOWN" ) )} -> Institutional custodian (regulated) | J9: {=_xlfn.LET( _xlpm.project,TRIM($C9), _xlpm.attribute,TRIM(IF(J$3<>"",J$3,J$2)), _xlfn.XLOOKUP( 1, (TRIM(Sources!$B$2:$B$461)=_xlpm.project)*(TRIM(Sources!$D$2:$D$461)=_xlpm.attribute), Sources!$E$2:$E$461, "UNKNOWN" ) )} -> SPV held | K9: {=_xlfn.LET( _xlpm.project,TRIM($C9), _xlpm.attribute,TRIM(IF(K$3<>"",K$3,K$2)), _xlfn.XLOOKUP( 1, (TRIM(Sources!$B$2:$B$461)=_xlpm.project)*(TRIM(Sources!$D$2:$D$461)=_xlpm.attribute), Sources!$E$2:$E$461, "UNKNOWN" ) )} -> AAA Arbitration; New York, New York | L9: {=_xlfn.LET( _xlpm.project,TRIM($C9), _xlpm.attribute,TRIM(IF(L$3<>"",L$3,L$2)), _xlfn.XLOOKUP( 1, (TRIM(Sources!$B$2:$B$461)=_xlpm.project)*(TRIM(Sources!$D$2:$D$461)=_xlpm.attribute), Sources!$E$2:$E$461, "UNKNOWN" ) )} -> Pro-rata claim on asset (share of pooled underlying) | M9: {=_xlfn.LET( _xlpm.project,TRIM($C9), _xlpm.attribute,TRIM(IF(M$3<>"",M$3,M$2)), _xlfn.XLOOKUP( 1, (TRIM(Sources!$B$2:$B$461)=_xlpm.project)*(TRIM(Sources!$D$2:$D$461)=_xlpm.attribute), Sources!$E$2:$E$461, "UNKNOWN" ) )} -> Redemption right; Income distribution right; Governance/voting | ... AB9: {=_xlfn.LET( _xlpm.project,TRIM($C9), _xlpm.attribute,TRIM(IF(AB$3<>"",AB$3,AB$2)), _xlfn.XLOOKUP( 1, (TRIM(Sources!$B$2:$B$461)=_xlpm.project)*(TRIM(Sources!$D$2:$D$461)=_xlpm.attribute), Sources!$E$2:$E$461, "UNKNOWN" ) )} -> KYC gated; Whitelisted only
B10: 7 | C10: Janus Henderson Anemoy AAA CLO Fund (JAAA) | D10: 46139 | E10: 7 | F10: {=_xlfn.LET( _xlpm.project,TRIM($C10), _xlpm.attribute,TRIM(IF(F$3<>"",F$3,F$2)), _xlfn.XLOOKUP( 1, (TRIM(Sources!$B$2:$B$461)=_xlpm.project)*(TRIM(Sources!$D$2:$D$461)=_xlpm.attribute), Sources!$E$2:$E$461, "UNKNOWN" ) )} -> BVI | G10: {=_xlfn.LET( _xlpm.project,TRIM($C10), _xlpm.attribute,TRIM(IF(G$3<>"",G$3,G$2)), _xlfn.XLOOKUP( 1, (TRIM(Sources!$B$2:$B$461)=_xlpm.project)*(TRIM(Sources!$D$2:$D$461)=_xlpm.attribute), Sources!$E$2:$E$461, "UNKNOWN" ) )} -> Bankruptcy remote vehicle: SPV | H10: {=_xlfn.LET( _xlpm.project,TRIM($C10), _xlpm.attribute,TRIM(IF(H$3<>"",H$3,H$2)), _xlfn.XLOOKUP( 1, (TRIM(Sources!$B$2:$B$461)=_xlpm.project)*(TRIM(Sources!$D$2:$D$461)=_xlpm.attribute), Sources!$E$2:$E$461, "UNKNOWN" ) )} -> UNKNOWN | I10: {=_xlfn.LET( _xlpm.project,TRIM($C10), _xlpm.attribute,TRIM(IF(I$3<>"",I$3,I$2)), _xlfn.XLOOKUP( 1, (TRIM(Sources!$B$2:$B$461)=_xlpm.project)*(TRIM(Sources!$D$2:$D$461)=_xlpm.attribute), Sources!$E$2:$E$461, "UNKNOWN" ) )} -> Institutional custodian (regulated) | J10: {=_xlfn.LET( _xlpm.project,TRIM($C10), _xlpm.attribute,TRIM(IF(J$3<>"",J$3,J$2)), _xlfn.XLOOKUP( 1, (TRIM(Sources!$B$2:$B$461)=_xlpm.project)*(TRIM(Sources!$D$2:$D$461)=_xlpm.attribute), Sources!$E$2:$E$461, "UNKNOWN" ) )} -> SPV held | K10: {=_xlfn.LET( _xlpm.project,TRIM($C10), _xlpm.attribute,TRIM(IF(K$3<>"",K$3,K$2)), _xlfn.XLOOKUP( 1, (TRIM(Sources!$B$2:$B$461)=_xlpm.project)*(TRIM(Sources!$D$2:$D$461)=_xlpm.attribute), Sources!$E$2:$E$461, "UNKNOWN" ) )} -> UNKNOWN | L10: {=_xlfn.LET( _xlpm.project,TRIM($C10), _xlpm.attribute,TRIM(IF(L$3<>"",L$3,L$2)), _xlfn.XLOOKUP( 1, (TRIM(Sources!$B$2:$B$461)=_xlpm.project)*(TRIM(Sources!$D$2:$D$461)=_xlpm.attribute), Sources!$E$2:$E$461, "UNKNOWN" ) )} -> Pro-rata claim on asset (share of pooled underlying) | M10: {=_xlfn.LET( _xlpm.project,TRIM($C10), _xlpm.attribute,TRIM(IF(M$3<>"",M$3,M$2)), _xlfn.XLOOKUP( 1, (TRIM(Sources!$B$2:$B$461)=_xlpm.project)*(TRIM(Sources!$D$2:$D$461)=_xlpm.attribute), Sources!$E$2:$E$461, "UNKNOWN" ) )} -> Redemption right; Interest entitlement | ... AB10: {=_xlfn.LET( _xlpm.project,TRIM($C10), _xlpm.attribute,TRIM(IF(AB$3<>"",AB$3,AB$2)), _xlfn.XLOOKUP( 1, (TRIM(Sources!$B$2:$B$461)=_xlpm.project)*(TRIM(Sources!$D$2:$D$461)=_xlpm.attribute), Sources!$E$2:$E$461, "UNKNOWN" ) )} -> Qualified investors only
B11: 8 | C11: Janus Henderson Anemoy Treasury Fund (JTRSY) | D11: 46139 | E11: 8 | F11: {=_xlfn.LET( _xlpm.project,TRIM($C11), _xlpm.attribute,TRIM(IF(F$3<>"",F$3,F$2)), _xlfn.XLOOKUP( 1, (TRIM(Sources!$B$2:$B$461)=_xlpm.project)*(TRIM(Sources!$D$2:$D$461)=_xlpm.attribute), Sources!$E$2:$E$461, "UNKNOWN" ) )} -> BVI | G11: {=_xlfn.LET( _xlpm.project,TRIM($C11), _xlpm.attribute,TRIM(IF(G$3<>"",G$3,G$2)), _xlfn.XLOOKUP( 1, (TRIM(Sources!$B$2:$B$461)=_xlpm.project)*(TRIM(Sources!$D$2:$D$461)=_xlpm.attribute), Sources!$E$2:$E$461, "UNKNOWN" ) )} -> Bankruptcy remote vehicle: SPV | H11: {=_xlfn.LET( _xlpm.project,TRIM($C11), _xlpm.attribute,TRIM(IF(H$3<>"",H$3,H$2)), _xlfn.XLOOKUP( 1, (TRIM(Sources!$B$2:$B$461)=_xlpm.project)*(TRIM(Sources!$D$2:$D$461)=_xlpm.attribute), Sources!$E$2:$E$461, "UNKNOWN" ) )} -> UNKNOWN | I11: {=_xlfn.LET( _xlpm.project,TRIM($C11), _xlpm.attribute,TRIM(IF(I$3<>"",I$3,I$2)), _xlfn.XLOOKUP( 1, (TRIM(Sources!$B$2:$B$461)=_xlpm.project)*(TRIM(Sources!$D$2:$D$461)=_xlpm.attribute), Sources!$E$2:$E$461, "UNKNOWN" ) )} -> Institutional custodian (regulated) | J11: {=_xlfn.LET( _xlpm.project,TRIM($C11), _xlpm.attribute,TRIM(IF(J$3<>"",J$3,J$2)), _xlfn.XLOOKUP( 1, (TRIM(Sources!$B$2:$B$461)=_xlpm.project)*(TRIM(Sources!$D$2:$D$461)=_xlpm.attribute), Sources!$E$2:$E$461, "UNKNOWN" ) )} -> Direct title (token holder is legal owner) | K11: {=_xlfn.LET( _xlpm.project,TRIM($C11), _xlpm.attribute,TRIM(IF(K$3<>"",K$3,K$2)), _xlfn.XLOOKUP( 1, (TRIM(Sources!$B$2:$B$461)=_xlpm.project)*(TRIM(Sources!$D$2:$D$461)=_xlpm.attribute), Sources!$E$2:$E$461, "UNKNOWN" ) )} -> UNKNOWN | L11: {=_xlfn.LET( _xlpm.project,TRIM($C11), _xlpm.attribute,TRIM(IF(L$3<>"",L$3,L$2)), _xlfn.XLOOKUP( 1, (TRIM(Sources!$B$2:$B$461)=_xlpm.project)*(TRIM(Sources!$D$2:$D$461)=_xlpm.attribute), Sources!$E$2:$E$461, "UNKNOWN" ) )} -> Pro-rata claim on asset (share of pooled underlying) | M11: {=_xlfn.LET( _xlpm.project,TRIM($C11), _xlpm.attribute,TRIM(IF(M$3<>"",M$3,M$2)), _xlfn.XLOOKUP( 1, (TRIM(Sources!$B$2:$B$461)=_xlpm.project)*(TRIM(Sources!$D$2:$D$461)=_xlpm.attribute), Sources!$E$2:$E$461, "UNKNOWN" ) )} -> Redemption right; Interest entitlement | ... AB11: {=_xlfn.LET( _xlpm.project,TRIM($C11), _xlpm.attribute,TRIM(IF(AB$3<>"",AB$3,AB$2)), _xlfn.XLOOKUP( 1, (TRIM(Sources!$B$2:$B$461)=_xlpm.project)*(TRIM(Sources!$D$2:$D$461)=_xlpm.attribute), Sources!$E$2:$E$461, "UNKNOWN" ) )} -> Qualified investors only; Whitelisted only
B12: 9 | C12: Ondo OUSG | D12: 46143 | E12: 9 | F12: {=_xlfn.LET( _xlpm.project,TRIM($C12), _xlpm.attribute,TRIM(IF(F$3<>"",F$3,F$2)), _xlfn.XLOOKUP( 1, (TRIM(Sources!$B$2:$B$461)=_xlpm.project)*(TRIM(Sources!$D$2:$D$461)=_xlpm.attribute), Sources!$E$2:$E$461, "UNKNOWN" ) )} -> USA | G12: {=_xlfn.LET( _xlpm.project,TRIM($C12), _xlpm.attribute,TRIM(IF(G$3<>"",G$3,G$2)), _xlfn.XLOOKUP( 1, (TRIM(Sources!$B$2:$B$461)=_xlpm.project)*(TRIM(Sources!$D$2:$D$461)=_xlpm.attribute), Sources!$E$2:$E$461, "UNKNOWN" ) )} -> Direct Issuer: LP | H12: {=_xlfn.LET( _xlpm.project,TRIM($C12), _xlpm.attribute,TRIM(IF(H$3<>"",H$3,H$2)), _xlfn.XLOOKUP( 1, (TRIM(Sources!$B$2:$B$461)=_xlpm.project)*(TRIM(Sources!$D$2:$D$461)=_xlpm.attribute), Sources!$E$2:$E$461, "UNKNOWN" ) )} -> UNKNOWN | I12: {=_xlfn.LET( _xlpm.project,TRIM($C12), _xlpm.attribute,TRIM(IF(I$3<>"",I$3,I$2)), _xlfn.XLOOKUP( 1, (TRIM(Sources!$B$2:$B$461)=_xlpm.project)*(TRIM(Sources!$D$2:$D$461)=_xlpm.attribute), Sources!$E$2:$E$461, "UNKNOWN" ) )} -> Institutional custodian (regulated) | J12: {=_xlfn.LET( _xlpm.project,TRIM($C12), _xlpm.attribute,TRIM(IF(J$3<>"",J$3,J$2)), _xlfn.XLOOKUP( 1, (TRIM(Sources!$B$2:$B$461)=_xlpm.project)*(TRIM(Sources!$D$2:$D$461)=_xlpm.attribute), Sources!$E$2:$E$461, "UNKNOWN" ) )} -> OTHER - Limited Partnership | K12: {=_xlfn.LET( _xlpm.project,TRIM($C12), _xlpm.attribute,TRIM(IF(K$3<>"",K$3,K$2)), _xlfn.XLOOKUP( 1, (TRIM(Sources!$B$2:$B$461)=_xlpm.project)*(TRIM(Sources!$D$2:$D$461)=_xlpm.attribute), Sources!$E$2:$E$461, "UNKNOWN" ) )} -> UNKNOWN | L12: {=_xlfn.LET( _xlpm.project,TRIM($C12), _xlpm.attribute,TRIM(IF(L$3<>"",L$3,L$2)), _xlfn.XLOOKUP( 1, (TRIM(Sources!$B$2:$B$461)=_xlpm.project)*(TRIM(Sources!$D$2:$D$461)=_xlpm.attribute), Sources!$E$2:$E$461, "UNKNOWN" ) )} -> Pro-rata claim on asset (share of pooled underlying) | M12: {=_xlfn.LET( _xlpm.project,TRIM($C12), _xlpm.attribute,TRIM(IF(M$3<>"",M$3,M$2)), _xlfn.XLOOKUP( 1, (TRIM(Sources!$B$2:$B$461)=_xlpm.project)*(TRIM(Sources!$D$2:$D$461)=_xlpm.attribute), Sources!$E$2:$E$461, "UNKNOWN" ) )} -> Redemption right; Interest entitlement | ... AB12: {=_xlfn.LET( _xlpm.project,TRIM($C12), _xlpm.attribute,TRIM(IF(AB$3<>"",AB$3,AB$2)), _xlfn.XLOOKUP( 1, (TRIM(Sources!$B$2:$B$461)=_xlpm.project)*(TRIM(Sources!$D$2:$D$461)=_xlpm.attribute), Sources!$E$2:$E$461, "UNKNOWN" ) )} -> Qualified investors only; KYC gated; Whitelisted only
B13: 10 | C13: BlackRock USD Institutional Digital Liquidity Fund - I Class (BUIDL-I) | D13: 46143 | E13: 10 | F13: {=_xlfn.LET( _xlpm.project,TRIM($C13), _xlpm.attribute,TRIM(IF(F$3<>"",F$3,F$2)), _xlfn.XLOOKUP( 1, (TRIM(Sources!$B$2:$B$461)=_xlpm.project)*(TRIM(Sources!$D$2:$D$461)=_xlpm.attribute), Sources!$E$2:$E$461, "UNKNOWN" ) )} -> BVI | G13: {=_xlfn.LET( _xlpm.project,TRIM($C13), _xlpm.attribute,TRIM(IF(G$3<>"",G$3,G$2)), _xlfn.XLOOKUP( 1, (TRIM(Sources!$B$2:$B$461)=_xlpm.project)*(TRIM(Sources!$D$2:$D$461)=_xlpm.attribute), Sources!$E$2:$E$461, "UNKNOWN" ) )} -> Direct Issuer: Ltd. | H13: {=_xlfn.LET( _xlpm.project,TRIM($C13), _xlpm.attribute,TRIM(IF(H$3<>"",H$3,H$2)), _xlfn.XLOOKUP( 1, (TRIM(Sources!$B$2:$B$461)=_xlpm.project)*(TRIM(Sources!$D$2:$D$461)=_xlpm.attribute), Sources!$E$2:$E$461, "UNKNOWN" ) )} -> UNKNOWN | I13: {=_xlfn.LET( _xlpm.project,TRIM($C13), _xlpm.attribute,TRIM(IF(I$3<>"",I$3,I$2)), _xlfn.XLOOKUP( 1, (TRIM(Sources!$B$2:$B$461)=_xlpm.project)*(TRIM(Sources!$D$2:$D$461)=_xlpm.attribute), Sources!$E$2:$E$461, "UNKNOWN" ) )} -> Institutional custodian (regulated) | J13: {=_xlfn.LET( _xlpm.project,TRIM($C13), _xlpm.attribute,TRIM(IF(J$3<>"",J$3,J$2)), _xlfn.XLOOKUP( 1, (TRIM(Sources!$B$2:$B$461)=_xlpm.project)*(TRIM(Sources!$D$2:$D$461)=_xlpm.attribute), Sources!$E$2:$E$461, "UNKNOWN" ) )} -> SPV held | K13: {=_xlfn.LET( _xlpm.project,TRIM($C13), _xlpm.attribute,TRIM(IF(K$3<>"",K$3,K$2)), _xlfn.XLOOKUP( 1, (TRIM(Sources!$B$2:$B$461)=_xlpm.project)*(TRIM(Sources!$D$2:$D$461)=_xlpm.attribute), Sources!$E$2:$E$461, "UNKNOWN" ) )} -> UNKNOWN | L13: {=_xlfn.LET( _xlpm.project,TRIM($C13), _xlpm.attribute,TRIM(IF(L$3<>"",L$3,L$2)), _xlfn.XLOOKUP( 1, (TRIM(Sources!$B$2:$B$461)=_xlpm.project)*(TRIM(Sources!$D$2:$D$461)=_xlpm.attribute), Sources!$E$2:$E$461, "UNKNOWN" ) )} -> Pro-rata claim on asset (share of pooled underlying) | M13: {=_xlfn.LET( _xlpm.project,TRIM($C13), _xlpm.attribute,TRIM(IF(M$3<>"",M$3,M$2)), _xlfn.XLOOKUP( 1, (TRIM(Sources!$B$2:$B$461)=_xlpm.project)*(TRIM(Sources!$D$2:$D$461)=_xlpm.attribute), Sources!$E$2:$E$461, "UNKNOWN" ) )} -> Redemption right; Income distribution right; Interest entitlement | ... AB13: {=_xlfn.LET( _xlpm.project,TRIM($C13), _xlpm.attribute,TRIM(IF(AB$3<>"",AB$3,AB$2)), _xlfn.XLOOKUP( 1, (TRIM(Sources!$B$2:$B$461)=_xlpm.project)*(TRIM(Sources!$D$2:$D$461)=_xlpm.attribute), Sources!$E$2:$E$461, "UNKNOWN" ) )} -> Qualified investors only; pre-approved investors only; Securitize Markets subscription
B14: 11 | C14: Hastra PRIME (PRIME) | D14: 46143 | E14: 11 | F14: {=_xlfn.LET( _xlpm.project,TRIM($C14), _xlpm.attribute,TRIM(IF(F$3<>"",F$3,F$2)), _xlfn.XLOOKUP( 1, (TRIM(Sources!$B$2:$B$461)=_xlpm.project)*(TRIM(Sources!$D$2:$D$461)=_xlpm.attribute), Sources!$E$2:$E$461, "UNKNOWN" ) )} -> BVI | G14: {=_xlfn.LET( _xlpm.project,TRIM($C14), _xlpm.attribute,TRIM(IF(G$3<>"",G$3,G$2)), _xlfn.XLOOKUP( 1, (TRIM(Sources!$B$2:$B$461)=_xlpm.project)*(TRIM(Sources!$D$2:$D$461)=_xlpm.attribute), Sources!$E$2:$E$461, "UNKNOWN" ) )} -> Limited Liability Company | H14: {=_xlfn.LET( _xlpm.project,TRIM($C14), _xlpm.attribute,TRIM(IF(H$3<>"",H$3,H$2)), _xlfn.XLOOKUP( 1, (TRIM(Sources!$B$2:$B$461)=_xlpm.project)*(TRIM(Sources!$D$2:$D$461)=_xlpm.attribute), Sources!$E$2:$E$461, "UNKNOWN" ) )} -> UNKNOWN | I14: {=_xlfn.LET( _xlpm.project,TRIM($C14), _xlpm.attribute,TRIM(IF(I$3<>"",I$3,I$2)), _xlfn.XLOOKUP( 1, (TRIM(Sources!$B$2:$B$461)=_xlpm.project)*(TRIM(Sources!$D$2:$D$461)=_xlpm.attribute), Sources!$E$2:$E$461, "UNKNOWN" ) )} -> Trust arrangement (intra-group, non-independent) | J14: {=_xlfn.LET( _xlpm.project,TRIM($C14), _xlpm.attribute,TRIM(IF(J$3<>"",J$3,J$2)), _xlfn.XLOOKUP( 1, (TRIM(Sources!$B$2:$B$461)=_xlpm.project)*(TRIM(Sources!$D$2:$D$461)=_xlpm.attribute), Sources!$E$2:$E$461, "UNKNOWN" ) )} -> Beneficial Ownership | K14: {=_xlfn.LET( _xlpm.project,TRIM($C14), _xlpm.attribute,TRIM(IF(K$3<>"",K$3,K$2)), _xlfn.XLOOKUP( 1, (TRIM(Sources!$B$2:$B$461)=_xlpm.project)*(TRIM(Sources!$D$2:$D$461)=_xlpm.attribute), Sources!$E$2:$E$461, "UNKNOWN" ) )} -> UNKNOWN | L14: {=_xlfn.LET( _xlpm.project,TRIM($C14), _xlpm.attribute,TRIM(IF(L$3<>"",L$3,L$2)), _xlfn.XLOOKUP( 1, (TRIM(Sources!$B$2:$B$461)=_xlpm.project)*(TRIM(Sources!$D$2:$D$461)=_xlpm.attribute), Sources!$E$2:$E$461, "UNKNOWN" ) )} -> Pro-rata claim on asset (share of pooled underlying) | M14: {=_xlfn.LET( _xlpm.project,TRIM($C14), _xlpm.attribute,TRIM(IF(M$3<>"",M$3,M$2)), _xlfn.XLOOKUP( 1, (TRIM(Sources!$B$2:$B$461)=_xlpm.project)*(TRIM(Sources!$D$2:$D$461)=_xlpm.attribute), Sources!$E$2:$E$461, "UNKNOWN" ) )} -> Redemption right; Interest entitlement | ... AB14: {=_xlfn.LET( _xlpm.project,TRIM($C14), _xlpm.attribute,TRIM(IF(AB$3<>"",AB$3,AB$2)), _xlfn.XLOOKUP( 1, (TRIM(Sources!$B$2:$B$461)=_xlpm.project)*(TRIM(Sources!$D$2:$D$461)=_xlpm.attribute), Sources!$E$2:$E$461, "UNKNOWN" ) )} -> KYC gated
B15: 12 | C15: Franklin OnChain U.S. Government Money Fund (BENJI) | D15: 46143 | E15: 12 | F15: {=_xlfn.LET( _xlpm.project,TRIM($C15), _xlpm.attribute,TRIM(IF(F$3<>"",F$3,F$2)), _xlfn.XLOOKUP( 1, (TRIM(Sources!$B$2:$B$461)=_xlpm.project)*(TRIM(Sources!$D$2:$D$461)=_xlpm.attribute), Sources!$E$2:$E$461, "UNKNOWN" ) )} -> USA | G15: {=_xlfn.LET( _xlpm.project,TRIM($C15), _xlpm.attribute,TRIM(IF(G$3<>"",G$3,G$2)), _xlfn.XLOOKUP( 1, (TRIM(Sources!$B$2:$B$461)=_xlpm.project)*(TRIM(Sources!$D$2:$D$461)=_xlpm.attribute), Sources!$E$2:$E$461, "UNKNOWN" ) )} -> Bankruptcy remote vehicle: Trust | H15: {=_xlfn.LET( _xlpm.project,TRIM($C15), _xlpm.attribute,TRIM(IF(H$3<>"",H$3,H$2)), _xlfn.XLOOKUP( 1, (TRIM(Sources!$B$2:$B$461)=_xlpm.project)*(TRIM(Sources!$D$2:$D$461)=_xlpm.attribute), Sources!$E$2:$E$461, "UNKNOWN" ) )} -> Yes (noncumulative shareholder voting rights; special meetings for matters requiring shareholder approval) | I15: {=_xlfn.LET( _xlpm.project,TRIM($C15), _xlpm.attribute,TRIM(IF(I$3<>"",I$3,I$2)), _xlfn.XLOOKUP( 1, (TRIM(Sources!$B$2:$B$461)=_xlpm.project)*(TRIM(Sources!$D$2:$D$461)=_xlpm.attribute), Sources!$E$2:$E$461, "UNKNOWN" ) )} -> Institutional custodian (regulated) | J15: {=_xlfn.LET( _xlpm.project,TRIM($C15), _xlpm.attribute,TRIM(IF(J$3<>"",J$3,J$2)), _xlfn.XLOOKUP( 1, (TRIM(Sources!$B$2:$B$461)=_xlpm.project)*(TRIM(Sources!$D$2:$D$461)=_xlpm.attribute), Sources!$E$2:$E$461, "UNKNOWN" ) )} -> Direct title (token holder is legal owner) | K15: {=_xlfn.LET( _xlpm.project,TRIM($C15), _xlpm.attribute,TRIM(IF(K$3<>"",K$3,K$2)), _xlfn.XLOOKUP( 1, (TRIM(Sources!$B$2:$B$461)=_xlpm.project)*(TRIM(Sources!$D$2:$D$461)=_xlpm.attribute), Sources!$E$2:$E$461, "UNKNOWN" ) )} -> UNKNOWN | L15: {=_xlfn.LET( _xlpm.project,TRIM($C15), _xlpm.attribute,TRIM(IF(L$3<>"",L$3,L$2)), _xlfn.XLOOKUP( 1, (TRIM(Sources!$B$2:$B$461)=_xlpm.project)*(TRIM(Sources!$D$2:$D$461)=_xlpm.attribute), Sources!$E$2:$E$461, "UNKNOWN" ) )} -> Pro-rata claim on asset (share of pooled underlying) | M15: {=_xlfn.LET( _xlpm.project,TRIM($C15), _xlpm.attribute,TRIM(IF(M$3<>"",M$3,M$2)), _xlfn.XLOOKUP( 1, (TRIM(Sources!$B$2:$B$461)=_xlpm.project)*(TRIM(Sources!$D$2:$D$461)=_xlpm.attribute), Sources!$E$2:$E$461, "UNKNOWN" ) )} -> Redemption right; Income distribution right; Governance/voting | ... AB15: {=_xlfn.LET( _xlpm.project,TRIM($C15), _xlpm.attribute,TRIM(IF(AB$3<>"",AB$3,AB$2)), _xlfn.XLOOKUP( 1, (TRIM(Sources!$B$2:$B$461)=_xlpm.project)*(TRIM(Sources!$D$2:$D$461)=_xlpm.attribute), Sources!$E$2:$E$461, "UNKNOWN" ) )} -> KYC gated; Whitelisted only
... B23: 20 | C23: mF-ONE (MF-ONE) | D23: 46154 | E23: 20 | F23: {=_xlfn.LET( _xlpm.project,TRIM($C23), _xlpm.attribute,TRIM(IF(F$3<>"",F$3,F$2)), _xlfn.XLOOKUP( 1, (TRIM(Sources!$B$2:$B$461)=_xlpm.project)*(TRIM(Sources!$D$2:$D$461)=_xlpm.attribute), Sources!$E$2:$E$461, "UNKNOWN" ) )} -> Germany | G23: {=_xlfn.LET( _xlpm.project,TRIM($C23), _xlpm.attribute,TRIM(IF(G$3<>"",G$3,G$2)), _xlfn.XLOOKUP( 1, (TRIM(Sources!$B$2:$B$461)=_xlpm.project)*(TRIM(Sources!$D$2:$D$461)=_xlpm.attribute), Sources!$E$2:$E$461, "UNKNOWN" ) )} -> Direct Issuer: GmbH | H23: {=_xlfn.LET( _xlpm.project,TRIM($C23), _xlpm.attribute,TRIM(IF(H$3<>"",H$3,H$2)), _xlfn.XLOOKUP( 1, (TRIM(Sources!$B$2:$B$461)=_xlpm.project)*(TRIM(Sources!$D$2:$D$461)=_xlpm.attribute), Sources!$E$2:$E$461, "UNKNOWN" ) )} -> UNKNOWN | I23: {=_xlfn.LET( _xlpm.project,TRIM($C23), _xlpm.attribute,TRIM(IF(I$3<>"",I$3,I$2)), _xlfn.XLOOKUP( 1, (TRIM(Sources!$B$2:$B$461)=_xlpm.project)*(TRIM(Sources!$D$2:$D$461)=_xlpm.attribute), Sources!$E$2:$E$461, "UNKNOWN" ) )} -> UNKNOWN | J23: {=_xlfn.LET( _xlpm.project,TRIM($C23), _xlpm.attribute,TRIM(IF(J$3<>"",J$3,J$2)), _xlfn.XLOOKUP( 1, (TRIM(Sources!$B$2:$B$461)=_xlpm.project)*(TRIM(Sources!$D$2:$D$461)=_xlpm.attribute), Sources!$E$2:$E$461, "UNKNOWN" ) )} -> N/A | K23: {=_xlfn.LET( _xlpm.project,TRIM($C23), _xlpm.attribute,TRIM(IF(K$3<>"",K$3,K$2)), _xlfn.XLOOKUP( 1, (TRIM(Sources!$B$2:$B$461)=_xlpm.project)*(TRIM(Sources!$D$2:$D$461)=_xlpm.attribute), Sources!$E$2:$E$461, "UNKNOWN" ) )} -> UNKNOWN | L23: {=_xlfn.LET( _xlpm.project,TRIM($C23), _xlpm.attribute,TRIM(IF(L$3<>"",L$3,L$2)), _xlfn.XLOOKUP( 1, (TRIM(Sources!$B$2:$B$461)=_xlpm.project)*(TRIM(Sources!$D$2:$D$461)=_xlpm.attribute), Sources!$E$2:$E$461, "UNKNOWN" ) )} -> Debt Instrument (Claim as a creditor) | M23: {=_xlfn.LET( _xlpm.project,TRIM($C23), _xlpm.attribute,TRIM(IF(M$3<>"",M$3,M$2)), _xlfn.XLOOKUP( 1, (TRIM(Sources!$B$2:$B$461)=_xlpm.project)*(TRIM(Sources!$D$2:$D$461)=_xlpm.attribute), Sources!$E$2:$E$461, "UNKNOWN" ) )} -> Redemption right | ... AB23: {=_xlfn.LET( _xlpm.project,TRIM($C23), _xlpm.attribute,TRIM(IF(AB$3<>"",AB$3,AB$2)), _xlfn.XLOOKUP( 1, (TRIM(Sources!$B$2:$B$461)=_xlpm.project)*(TRIM(Sources!$D$2:$D$461)=_xlpm.attribute), Sources!$E$2:$E$461, "UNKNOWN" ) )} -> Qualified investors only; KYC gated; Whitelisted only

Sheet Sources
A1: ID | B1: System | C1: Component | D1: Attribute | E1: Characteristic/ Value | F1: Reason | G1: Date of classification / access of docs (YYYY-MM-DD) | H1: Source Type (Official, on chain data, third party, regulatory finding ...) | I1: Confidence level | J1: text/info from link | K1: links:
A2: 1 | B2: Tether Gold (XAUt) | C2: Governance | D2: Incorporation Jurisdiction | E2: El Salvador | F2: Issuer is incorporated under El Salvador law. | G2: 46112 | H2: Official | I2: High | J2: a company incorporated and in effect under the Laws of El Salvador | K2: https://gold.tether.to/Relevant%20Information%20Document%20-%20TG%20Commodities%2C%20S.A.%20de%20C.V.%20%28ENG%29.pdf
B3: Tether Gold (XAUt) | C3: Governance | D3: Legal Entity (Wrapper) | E3: Direct Issuer: SA de C.V. | F3: TG Commodities is the issuing and redeeming entity. | G3: 46112 | H3: Official | I3: High | J3: TG Commodities is the customer-facing entity that issues and redeems Tether Gold Tokens | K3: https://gold.tether.to/Relevant%20Information%20Document%20-%20TG%20Commodities%2C%20S.A.%20de%20C.V.%20%28ENG%29.pdf
B4: Tether Gold (XAUt) | C4: Governance | D4: Voting | E4: N/A | F4: The official RID describes XAUt as an issuer-managed, gold-backed ERC-20 token and does not disclose any token-holder governance or voting mechanism. | G4: 46139 | H4: Official documentation | I4: Medium | J4: RID: each token represents an interest in one fine troy ounce of LBMA gold; TG Commodities issues/redeems; XAUt is ERC-20 on Ethereum. No voting or governance voting process is disclosed in the reviewed official source. | K4: https://gold.tether.to/Relevant%20Information%20Document%20-%20TG%20Commodities%2C%20S.A.%20de%20C.V.%20%28ENG%29.pdf
B5: Tether Gold (XAUt) | C5: Asset | D5: Custody Arrangement | E5: Vault storage (physical assets) | F5: Gold reserves are stored in a Swiss vault. | G5: 46112 | H5: Official | I5: High | J5: The Gold Reserves are held by the custodian in a vault in Switzerland | K5: https://gold.tether.to/Relevant%20Information%20Document%20-%20TG%20Commodities%2C%20S.A.%20de%20C.V.%20%28ENG%29.pdf
B6: Tether Gold (XAUt) | C6: Asset | D6: Ownership Structure | E6: Beneficial ownership (custodian holds legal title on behalf of user) | F6: Gold reserves are held by a custodian on behalf of holders. | G6: 46112 | H6: Official | I6: High | J6: the Gold Reserves are held by a custodian on behalf of XAU₮ holders | K6: https://gold.tether.to/Relevant%20Information%20Document%20-%20TG%20Commodities%2C%20S.A.%20de%20C.V.%20%28ENG%29.pdf
B7: Tether Gold (XAUt) | C7: Asset | D7: Dispute Forum | E7: CPR Arbitration; BVI law | F7: RID states BVI law and CPR arbitration. | G7: 46112 | H7: Official | I7: High | J7: shall be governed by the Laws of the BVI and will be subject to and finally resolved by confidential, binding arbitration | K7: https://gold.tether.to/Relevant%20Information%20Document%20-%20TG%20Commodities%2C%20S.A.%20de%20C.V.%20%28ENG%29.pdf
B8: Tether Gold (XAUt) | C8: Asset | D8: Claim Type | E8: Direct Claim on asset | F8: Each token represents ownership of one fine troy ounce on a specific bar. | G8: 46112 | H8: Official | I8: High | J8: represent ownership of an undivided specific interest in one fine troy ounce of gold | K8: https://gold.tether.to/Relevant%20Information%20Document%20-%20TG%20Commodities%2C%20S.A.%20de%20C.V.%20%28ENG%29.pdf
B9: Tether Gold (XAUt) | C9: Asset | D9: Entitlements | E9: Redemption right | F9: Verified customers can redeem for physical delivery or sale proceeds. | G9: 46112 | H9: Official | I9: High | J9: If a KYC Verified Customer wishes to redeem their Tether Gold Tokens | K9: https://gold.tether.to/Relevant%20Information%20Document%20-%20TG%20Commodities%2C%20S.A.%20de%20C.V.%20%28ENG%29.pdf
B10: Tether Gold (XAUt) | C10: Asset | D10: Asset Type | E10: Commodity (GOLD) | F10: Underlying asset is physical gold. | G10: 46112 | H10: Official | I10: High | J10: one fine troy ounce of gold | K10: https://gold.tether.to/Relevant%20Information%20Document%20-%20TG%20Commodities%2C%20S.A.%20de%20C.V.%20%28ENG%29.pdf
B11: Tether Gold (XAUt) | C11: Asset | D11: Third-Party Audit | E11: Yes; quarterly; https://tether.to/en/transparency | F11: RID says gold reserve reports and independent auditors’ reports are prepared quarterly. | G11: 46112 | H11: Official | I11: High | J11: we will publish reports on the Gold Reserves quarterly | K11: https://gold.tether.to/Relevant%20Information%20Document%20-%20TG%20Commodities%2C%20S.A.%20de%20C.V.%20%28ENG%29.pdf
B12: Tether Gold (XAUt) | C12: Asset | D12: On-Chain Proof | E12: other | F12: Tether Gold describes XAUt as a tokenized claim on allocated physical gold, with an issuer-run “Look-up Website” that maps on-chain addresses to specific gold bars, plus periodic reserve attestations, no on chain PoR | G12: 46112 | H12: Official | I12: Medium | J12: we will publish reports on the Gold Reserves quarterly, that will be available on the Tether’s Transparency page https://tether.to/en/transparency (the “Transparency Page”). In addition, Independent Auditors’ Reports on those Gold Reserve reports will be prepared by an independent third party accounting rm, | K12: https://gold.tether.to/Relevant%20Information%20Document%20-%20TG%20Commodities%2C%20S.A.%20de%20C.V.%20%28ENG%29.pdf
B13: Tether Gold (XAUt) | C13: Token Properties | D13: Divisibility | E13: Fractionalized | F13: XAUt can be divided to six decimal places. | G13: 46112 | H13: Official | I13: High | J13: can be fractionalized up to six decimal places | K13: https://gold.tether.to/Relevant%20Information%20Document%20-%20TG%20Commodities%2C%20S.A.%20de%20C.V.%20%28ENG%29.pdf
B14: Tether Gold (XAUt) | C14: Token Properties | D14: Settlement Form(s) | E14: Combination | F14: Redemption can settle as physical delivery or sale proceeds in USD. | G14: 46112 | H14: Official | I14: High | J14: physical delivery of the underlying full gold bar in Switzerland, or may request that Tether Gold attempt to sell their bullion bar | K14: https://gold.tether.to/Relevant%20Information%20Document%20-%20TG%20Commodities%2C%20S.A.%20de%20C.V.%20%28ENG%29.pdf
... B24: Tether Gold (XAUt) | C24: Economy | D24: Primary Market Access | E24: KYC gated | F24: Direct purchases and redemptions require successful KYC verification. | G24: 46112 | H24: Official | I24: High | J24: KYC Verified Customers can purchase and redeem Tether Gold Tokens directly through the Tether Gold Website | K24: https://gold.tether.to/Relevant%20Information%20Document%20-%20TG%20Commodities%2C%20S.A.%20de%20C.V.%20%28ENG%29.pdf
A25: 2 | B25: BUIDL | C25: Governance | D25: Incorporation Jurisdiction | E25: BVI | F25: SEC Form D lists the issuer as incorporated in the British Virgin Islands. | G25: 46112 | H25: Regulatory finding | I25: High | J25: Jurisdiction of Incorporation/Organization VIRGIN ISLANDS, BRITISH | K25: https://www.sec.gov/Archives/edgar/data/2013810/000201439024000001/xslFormDX01/primary_doc.xml
B26: BUIDL | C26: Governance | D26: Legal Entity (Wrapper) | E26: Direct Issuer: Ltd. | F26: SEC filing identifies the issuing entity as a limited company. | G26: 46112 | H26: Regulatory finding | I26: High | J26: Entity Type ... Other (Specify) Limited Company | K26: https://www.sec.gov/Archives/edgar/data/2013810/000201439024000001/xslFormDX01/primary_doc.xml
B27: BUIDL | C27: Governance | D27: Voting | E27: No token-holder voting system identified for the tokenized fund; BUIDL is not DAO-governed. | F27: The fund shares are described as non-voting participating Class A Shares issued as digital tokens; a risk assessment states BUIDL is not subject to DAO governance. | G27: 46139 | H27: Third-party risk assessment; official/regulatory context | I27: High | J27: Aave/LlamaRisk: BUIDL presents non-voting, participating Class A Shares issued as digital tokens; BUIDL is not subject to DAO governance. SEC Form D identifies the issuer as BlackRock USD Institutional Digital Liquidity Fund Ltd. | K27: https://governance.aave.com/t/arfc-ustb-buidl-gsm/19299 https://www.sec.gov/Archives/edgar/data/2013810/000201439024000001/xslFormDX01/primary_doc.xml
B28: BUIDL | C28: Asset | D28: Custody Arrangement | E28: Institutional custodian (regulated) | F28: BNY Mellon is named as custodian. | G28: 46112 | H28: Official | I28: High | J28: Bank of New York Mellon will serve as the custodian of the Fund's assets and its administrator | K28: https://www.businesswire.com/news/home/20240320771318/en/BlackRock-Launches-Its-First-Tokenized-Fund-BUIDL-on-the-Ethereum-Network
B29: BUIDL | C29: Asset | D29: Ownership Structure | E29: Beneficial ownership (custodian holds legal title on behalf of user) | F29: Investors hold tokenized fund shares while the underlying fund assets are custodied by BNY Mellon. | G29: 46112 | H29: Official | I29: Medium | J29: Bank of New York Mellon will serve as the custodian of the Fund's assets ... Securitize will act as a transfer agent and tokenization platform, managing the tokenized shares | K29: https://www.businesswire.com/news/home/20240320771318/en/BlackRock-Launches-Its-First-Tokenized-Fund-BUIDL-on-the-Ethereum-Network
B30: BUIDL | C30: Asset | D30: Dispute Forum | E30: Delaware, Disputes resolved in New York | F30: Rule of law: Delaware. Disputes are to be resolved by the Supreme Court of the State of New York | G30: 46112 | H30: Third party | I30: Medium | J30: Dispute Resolution Country Delaware | K30: https://forum.arbitrum.foundation/t/securitize-markets-buidl-step-application/23652
B31: BUIDL | C31: Asset | D31: Claim Type | E31: Pro-rata claim on asset (share of pooled underlying) | F31: The security offered is a pooled fund interest represented as tokenized shares. | G31: 46112 | H31: Regulatory finding | I31: Medium | J31: Type(s) of Securities Offered ... Pooled Investment Fund Interests | K31: https://www.sec.gov/Archives/edgar/data/2013810/000201439024000001/xslFormDX01/primary_doc.xml
B32: BUIDL | C32: Asset | D32: Entitlements | E32: Redemption right; Income distribution right | F32: Official materials disclose both distributions and redemptions. | G32: 46112 | H32: Official | I32: High | J32: reporting on Fund subscriptions, redemptions, and distributions | K32: https://www.businesswire.com/news/home/20240320771318/en/BlackRock-Launches-Its-First-Tokenized-Fund-BUIDL-on-the-Ethereum-Network
B33: BUIDL | C33: Asset | D33: Asset Type | E33: Fixed income (government/corporate bonds) | F33: The underlying exposure is U.S. Treasury debt and repo. | G33: 46112 | H33: Official | I33: High | J33: The Fund invests 100% of its total assets in cash, U.S. Treasury bills, and repurchase agreements | K33: https://www.businesswire.com/news/home/20240320771318/en/BlackRock-Launches-Its-First-Tokenized-Fund-BUIDL-on-the-Ethereum-Network
B34: BUIDL | C34: Asset | D34: Third-Party Audit | E34: Yes; annual by PwC | F34: PwC is appointed as auditor for the year-end period. | G34: 46112 | H34: Official | I34: High | J34: Auditor: PwC | K34: https://app.rwa.xyz/assets/BUIDL
B35: BUIDL | C35: Asset | D35: On-Chain Proof | E35: UNKNOWN | F35: No explicit proof-of-reserves or similar on-chain proof mechanism was identified in the reviewed materials. | G35: 46112 | H35: Official | I35: Low | J35: providing instantaneous and transparent settlement | K35: https://www.businesswire.com/news/home/20240320771318/en/BlackRock-Launches-Its-First-Tokenized-Fund-BUIDL-on-the-Ethereum-Network
B36: BUIDL | C36: Token Properties | D36: Divisibility | E36: Fractionalized | F36: Token supply is shown with decimal precision. | G36: 46112 | H36: Third party | I36: Medium | J36: Token Supply 1,998,788,657.94 | K36: https://app.rwa.xyz/assets/BUIDL
B37: BUIDL | C37: Token Properties | D37: Settlement Form(s) | E37: Combination | F37: Primary-market base assets include both fiat and stablecoin rails. | G37: 46112 | H37: Third party | I37: Medium | J37: Base Assets USDC USD | K37: https://app.rwa.xyz/assets/BUIDL
... B47: BUIDL | C47: Economy | D47: Primary Market Access | E47: Qualified investors only | F47: Official launch materials limit direct participation to qualified investors. | G47: 46112 | H47: Official | I47: High | J47: BUIDL will provide qualified investors with the opportunity to earn U.S. dollar yields by subscribing to the Fund through Securitize Markets, LLC | K47: https://www.businesswire.com/news/home/20240320771318/en/BlackRock-Launches-Its-First-Tokenized-Fund-BUIDL-on-the-Ethereum-Network
A48: 3 | B48: PAX Gold | C48: Governance | D48: Incorporation Jurisdiction | E48: USA | F48: Issuer is a U.S. national banking association. | G48: 46113 | H48: Official | I48: High | J48: Paxos Trust Company, NA, a national banking association organized under the laws of the United States | K48: https://www.paxos.com/terms-and-conditions/general-terms-and-conditions
B49: PAX Gold | C49: Governance | D49: Legal Entity (Wrapper) | E49: Direct Issuer: N.A. | F49: PAX Gold is managed by Paxos Trust Company, N.A. | G49: 46113 | H49: Official | I49: High | J49: gold denominated and backed token managed by Paxos Trust Company, NA | K49: https://www.paxos.com/terms-and-conditions/pax-gold-terms-conditions
B50: PAX Gold | C50: Governance | D50: Voting | E50: No voting system identified. | F50: Official PAXG terms describe asset ownership, ERC-20 transferability, conversion and Paxos control rights; no holder governance or voting system is disclosed. | G50: 46139 | H50: Official documentation | I50: Medium | J50: PAXG terms: PAXG can be transferred, traded, kept, used for payment, or converted with Paxos; each token equals one fine troy ounce of London Good Delivery gold. No governance voting process is disclosed in the reviewed terms. | K50: https://www.paxos.com/terms-and-conditions/pax-gold-terms-conditions
B51: PAX Gold | C51: Asset | D51: Custody Arrangement | E51: Vault storage (physical assets) | F51: Backing gold is stored in LBMA vaults in London. | G51: 46113 | H51: Official | I51: High | J51: Each Pax Gold (PAXG) token is backed by one fine troy ounce of gold, stored in LBMA vaults in London | K51: https://www.paxos.com/pax-gold
B52: PAX Gold | C52: Asset | D52: Ownership Structure | E52: Beneficial ownership (custodian holds legal title on behalf of user) | F52: Terms describe beneficial ownership of allocated gold rather than direct legal title. | G52: 46113 | H52: Official | I52: High | J52: you will become the beneficial owner of those tokens and the underlying allocated gold | K52: https://www.paxos.com/terms-and-conditions/pax-gold-terms-conditions
B53: PAX Gold | C53: Asset | D53: Dispute Forum | E53: Binding arbitration; New York law | F53: Disputes involving Paxos Trust customers are arbitrated in New York under New York law. | G53: 46113 | H53: Official | I53: High | J53: customers of Paxos Trust by arbitration in New York, New York ... governed by the laws of the State of New York | K53: https://www.paxos.com/terms-and-conditions/general-terms-and-conditions
B54: PAX Gold | C54: Asset | D54: Claim Type | E54: Pro-rata claim on asset (share of pooled underlying) | F54: Terms characterize PAXG as a warehouse receipt for a pro-rata portion of allocated gold. | G54: 46113 | H54: Official | I54: High | J54: representing your beneficial ownership of a pro rata portion of Allocated Gold | K54: https://www.paxos.com/terms-and-conditions/pax-gold-terms-conditions
B55: PAX Gold | C55: Asset | D55: Entitlements | E55: Redemption right | F55: Holders can convert or redeem PAXG into USD, unallocated gold, or allocated gold. | G55: 46113 | H55: Official | I55: High | J55: convert PAXG for US dollars, Unallocated Gold, and Allocated Gold | K55: https://www.paxos.com/terms-and-conditions/pax-gold-terms-conditions
B56: PAX Gold | C56: Asset | D56: Asset Type | E56: Commodity (GOLD) | F56: Underlying asset is physical gold. | G56: 46113 | H56: Official | I56: High | J56: Each PAXG token is equal to one fine troy ounce of London Good Delivery gold | K56: https://www.paxos.com/terms-and-conditions/pax-gold-terms-conditions
B57: PAX Gold | C57: Asset | D57: Third-Party Audit | E57: Yes; monthly; https://www.paxos.com/paxg-transparency | F57: Paxos publishes monthly attestation reports from an independent accounting firm. | G57: 46113 | H57: Official | I57: High | J57: Paxos publishes attestation reports each month | K57: https://www.paxos.com/paxg-transparency
B58: PAX Gold | C58: Asset | D58: On-Chain Proof | E58: Other (Lookup tool) | F58: Paxos provides an address-based gold allocation lookup tool rather than a standard proof-of-reserves oracle. | G58: 46113 | H58: Official | I58: High | J58: Use this tool to lookup the serial number and information about your gold | K58: https://www.paxos.com/pax-gold
...

Sheet DefiLlama Top 100 RWA 
B2: As of February 2026, list by Market Capitalization
B3: Source link: | C3: https://defillama.com/rwa
B4: Rank | C4: Name | D4: Type | E4: RWA Classification | F4: Access Model | G4: Category | H4: Asset Class | I4: DeFi Active TVL | J4: Active Marketcap | K4: Onchain Marketcap | L4: Token Price | M4: Issuer | N4: Redeemable | O4: Attestations | P4: CEX Listed | Q4: KYC to Mint or Redeem | R4: KYC/Allowlisted/Whitelisted to Transfer/Hold | S4: Transferable | T4: Self Custody
B5: 1 | C5: Tether Gold (XAUT) | D5: Asset | E5: RWA | F5: Permissionless | G5: Tokenized Gold & Commodities | H5: Allocated gold token | I5: $178.54m | J5: $3.57b | K5: $3.57b | L5: 5009 | M5: TG Commodities Limited | N5: Yes | O5: Yes | P5: Yes | Q5: Yes | S5: Yes | T5: Yes
B6: 2 | C6: BlackRock BUIDL (BUIDL) | D6: Asset | E6: RWA | F6: Permissioned | G6: Tokenized Funds (T-Bills, Bonds, MMFs) | H6: Money market fund | I6: $22.8m | J6: $2.363b | K6: $2.363b | M6: BlackRock USD Institutional Digital Liquidity Fund Ltd. | N6: Yes | O6: Yes | Q6: Yes | R6: Yes | S6: Yes | T6: Yes
B7: 3 | C7: PAX Gold (PAXG) | D7: Asset | E7: RWA | F7: Permissionless | G7: Tokenized Gold & Commodities | H7: Allocated gold token | I7: $15.54m | J7: $2.218b | K7: $2.315b | L7: 5043 | M7: Paxos Trust Company, LLC | N7: Yes | O7: Yes | P7: Yes | Q7: Yes | S7: Yes | T7: Yes
B8: 4 | C8: US Yield Coin (USYC) | D8: Asset | E8: RWA | F8: Permissioned | G8: Tokenized Funds (T-Bills, Bonds, MMFs) | H8: Money market fund | I8: $37.13m | J8: $1.592b | K8: $1.592b | M8: Hashnote International Short Duration Yield Fund Ltd | N8: Yes | O8: Yes | P8: Yes | Q8: Yes | R8: Yes | S8: Yes | T8: Yes
B9: 5 | C9: Superstate USTB (USTB) | D9: Asset | E9: RWA | F9: Permissioned | G9: Tokenized Funds (T-Bills, Bonds, MMFs) | H9: Tokenized T-bills | I9: $79.64m | J9: $580.8m | K9: $755.21m | L9: 10.98 | M9: Superstate Trust | N9: Yes | O9: Yes | Q9: Yes | R9: Yes | S9: Yes | T9: Yes
B10: 6 | C10: WisdomTree Treasury Money Market Digital Fund (WTGXX) | D10: Asset | E10: RWA | F10: Permissioned | G10: Tokenized Funds (T-Bills, Bonds, MMFs) | H10: Money market fund | I10: $18.9m | J10: $583.57m | K10: $729.1m | L10: 1 | M10: WisdomTree Digital Trust | N10: Yes | O10: Yes | Q10: Yes | R10: Yes | S10: Yes | T10: Yes
B11: 7 | C11: Janus Henderson Anemoy AAA CLO Fund (JAAA) | D11: Asset | E11: RWA | F11: Permissioned | G11: RWA Lending / Private Credit | H11: Credit / corporate bond fund | I11: $2.55m | J11: $4.55m | K11: $721.93m | L11: 1.02 | M11: Anemoy Capital SPC Limited | N11: Yes | O11: Yes | Q11: Yes | R11: Yes | S11: Yes | T11: Yes
B12: 8 | C12: Janus Henderson Anemoy Treasury Fund (JTRSY) | D12: Asset | E12: RWA | F12: Permissioned | G12: Tokenized Funds (T-Bills, Bonds, MMFs) | H12: Tokenized T-bills | I12: 0 | J12: $1.46m | K12: $567.69m | L12: 1.09 | M12: Anemoy Capital SPC Limited | N12: Yes | O12: Yes | Q12: Yes | R12: Yes | S12: Yes | T12: Yes
B13: 9 | C13: Ondo OUSG (OUSG) | D13: Asset | E13: RWA | F13: Permissioned | G13: Tokenized Funds (T-Bills, Bonds, MMFs) | H13: Tokenized T-bills | I13: $38.55m | J13: $463.46m | K13: $551.07m | L13: 114.29 | M13: Ondo I LP | N13: Yes | O13: Yes | Q13: Yes | R13: Yes | S13: Yes | T13: Yes
B14: 10 | C14: BlackRock USD Institutional Digital Liquidity Fund - I Class (BUIDL-I) | D14: Asset | E14: RWA | F14: Permissioned | G14: Tokenized Funds (T-Bills, Bonds, MMFs) | H14: Money market fund | I14: 0 | J14: $279.78m | K14: $414.95m | L14: 1 | M14: BlackRock USD Institutional Digital Liquidity Fund Ltd. | N14: Yes | O14: Yes | Q14: Yes | R14: Yes | S14: Yes | T14: Yes
B15: 11 | C15: Hastra PRIME (PRIME) | D15: Asset | E15: RWA | F15: Permissionless | G15: RWA Yield / Wrapper | H15: Yield bearing RWA pool | I15: $283.66m | K15: $296.7m | L15: 1.01 | M15: Hastra | N15: Yes | O15: Yes | Q15: Yes | S15: Yes | T15: Yes
